<mujoco>
    <asset>
        <texture name="grid" type="2d" builtin="checker" width="512" height="512" rgb1=".1 .2 .3" rgb2=".2 .3 .4"/>
        <material name="grid" texture="grid" texrepeat="1 1" texuniform="true" reflectance=".2"/>
    </asset>

    <worldbody>
        <light diffuse=".5 .5 .5" pos="0 0 3" dir="0 0 -1" />
        <geom type="plane" size="1 1 .1" material="grid" />

        <!-- Fixed gear body -->
        <body name="stand" pos="0 0 0">
            <geom type="box" size=".05 .01 .02" pos="0 -.021 0" rgba="1 1 1 1" />
            <geom type="box" size=".05 .01 .02" pos="0 .021 0" rgba="1 1 1 1" />
            <body name="pend_arm" pos="0 0 .015">
                <geom type="capsule" size=".01" fromto="0 0 0 0 0 0.207" rgba="1 1 1 1" />
                <joint type="hinge" axis="0 1 0" pos="0 0 0" limited="true" range="-30 30" />

                <body name="wheel" pos="0 0.02 0.207">
                    <!-- Central cylinder representing the wheel -->
                    <geom type="cylinder" size="0.105 0.01" rgba=".2 .2 .2 1" euler="90 0 0"/>
                    
                    <!-- Spokes -->
                    <geom type="box" size="0.02 0.001 0.05" pos="0 0.02 0.05" euler="0 0 0" rgba="0.3 0.3 0.3 1"/>
                    <!-- <geom type="box" size="0.025 0.3 0.05" pos="0 0 0" euler="0 0 1.57" rgba="0.3 0.3 0.3 1"/>
                    <geom type="box" size="0.025 0.3 0.05" pos="0 0 0" euler="0 0 3.14" rgba="0.3 0.3 0.3 1"/>
                    <geom type="box" size="0.025 0.3 0.05" pos="0 0 0" euler="0 0 4.71" rgba="0.3 0.3 0.3 1"/> -->

                    <!-- Revolute joint for wheel rotation -->
                    <joint name="wheel_rot" type="hinge" pos="0 0 0" axis="0 1 0" damping=".1"/>

                    <camera name="wheel_cam" pos="0 0.5 0" zaxis="0 1 0" fovy="45" mode="trackcom" />
                </body>
            </body>
        </body>
    </worldbody>

    <actuator>
        <!-- Agregar medidas en el slider (-a, a) -->
        <motor gear="1" joint="wheel_rot" name="motor"/>
    </actuator>
</mujoco>