<mujoco>
    <asset>
        <texture name="grid" type="2d" builtin="checker" width="512" height="512" rgb1=".1 .2 .3" rgb2=".2 .3 .4"/>
        <material name="grid" texture="grid" texrepeat="1 1" texuniform="true" reflectance=".2"/>
    </asset>

    <worldbody>
        <light diffuse=".5 .5 .5" pos="0 0 3" dir="0 0 -1" />
        <geom type="plane" size="2 2 .1" material="grid" />

        <body name="base" pos="0 0 0.1">
            <geom type="cylinder" size="0.02 0.6" euler="90 0 0"/>
            <body name="car" pos="0 0 0.031">
                <joint name="car_joint" type="slide" axis="0 1 0" limited="true" range="-.6 .6"/>
                <geom type="box" size=".02 .02 .01" mass=".5" />

                <body name="pend" pos="0 0 0.01">
                    <joint name="pend_joint" axis="1 0 0" limited="true" range="-30 30"/>
                    <geom type="capsule" fromto="0 0 0 0 0 0.6" size="0.02" mass=".2" />
                </body>
            </body>
        </body>        
    </worldbody>

    <actuator>
        <motor gear="8" joint="car_joint" name="car_motor"/>
        <damper joint="car_joint" name="car_damper" kv="10" ctrlrange="0 1" />
        <damper joint="pend_joint" name="pendulum_damper" kv="1" ctrlrange="0 1" />
    </actuator>
</mujoco>