<mujoco>
    <asset>
        <texture name="grid" type="2d" builtin="checker" width="512" height="512" rgb1=".9 .9 .9" rgb2=".3 .3 .9"/>
        <material name="grid" texture="grid" texrepeat="1 1" texuniform="true" reflectance=".2"/>
    </asset>

    <worldbody>

        <camera name="default_view" pos=".3 .5 .3" mode="fixed" />

        <light diffuse="1 1 1" pos="0 0 3" dir="0 0 -1" />
        <geom type="plane" size="2 2 .1" material="grid" />

        <body name="base" pos="0 0 0.01">
            <geom type="cylinder" size="0.02 1" euler="90 0 0" rgba=".3 .5 .8 1" />

            <body name="car" pos="0 0 0.031">
                <joint name="car_joint" type="slide" axis="0 1 0" limited="true" range="-1 1"  />
                <geom type="box" size=".02 .02 .01" mass=".5" rgba="0 0 0 1" />

                <body name="pend" pos="0 0 0.01">
                    <joint name="pend_joint" axis="1 0 0" limited="true" range="-10 10"/>
                    <geom type="capsule" fromto="0 0 0 0 0 0.6" size="0.01" rgba=".9 .9 .9 1" mass=".2" />
                </body>
            </body>
        </body>

        <body name="fixed_end1" pos="0 1.04 .03">
            <geom type="box" size=".03 .035 .03" rgba="0 0 0 1" />
        </body>

        <body name="fixed_end2" pos="0 -1.04 .03">
            <geom type="box" size=".03 .035 .03" rgba="0 0 0 1" />
        </body>  
    </worldbody>

    <actuator>
        <motor gear="8" joint="car_joint" name="motor" ctrlrange="-1 1"/>
        <damper joint="car_joint" name="car_damper" kv="10" ctrlrange="0 .5" />
        <damper joint="pend_joint" name="pendulum_damper" kv="1" ctrlrange="0 .5" />
    </actuator>

    <sensor>
        <jointpos name="theta" joint="pend_joint"/>
        <jointvel name="theta_dot" joint="pend_joint"/>
    </sensor>
</mujoco>