<mujoco>
    <asset>
        <texture name="grid" type="2d" builtin="checker" width="512" height="512" rgb1=".9 .9 .9" rgb2=".3 .3 .9"/>
        <material name="grid" texture="grid" texrepeat="1 1" texuniform="true" reflectance=".2"/>
    </asset>

    <worldbody>
        <light diffuse=".9 .9 .9" pos="0 0.3 2" dir="0 0 -1" />
        <geom type="plane" size="1 1 .1" material="grid" />

        <!-- Fixed gear body, connected to the actuator -->
        <body name="gear" pos=".5 0 0.1">
            <!-- Gear joint - Allow it to rotate -->
            <!-- Adjust gear to move between -60 and 60 degrees -->
            <joint type="hinge" name="gear_joint" axis="0 1 0" damping=".5"/>
            <geom type="cylinder" size="0.05 0.005" euler="90 0 0" pos="0 .015 0" rgba=".2 .2 .2 1"/>
            <!-- Pole, connected to the gear and with 1 dof to be comfortably attached to the gear -->
            <body name="pole" pos="-0.03 0 0">
                <joint type="hinge" name="pole_joint" axis="0 1 0"/>
                <geom type="capsule" fromto="0 0 0 0 0 0.2" size="0.01" rgba="1 1 1 1"/>
                <!-- The beam where the ball will be attached -->
                <body name="beam" pos="0 0 0.2">
                    <geom type="capsule" fromto="0 0 0 -1 0 0" size="0.01" rgba="1 1 1 1"/>
                    <joint name="beam_joint" type="hinge" axis="0 1 0" pos="0 0 0" />
                    <!-- The ball to be controlled -->
                    <body name="ball" pos="-.2 0 0.02">
                        <joint name="ball_joint" type="slide" axis="1 0 0" pos="0 0 0" limited="true" range="-0.8 0.2"/>
                        <geom type="sphere" name="control_ball" size="0.015" mass="0.11" rgba="1 .2 .2 1"/>
                    </body>

                    <!-- Attempt to fix the beam to the world -->
                    <body name="fixed_end1" pos="-1 0 -.3">
                        <joint type="ball" />
                        <geom size=".001 .001 .001"/>
                    </body>
                </body> 
            </body>
        </body>

        
        
    </worldbody>

    <equality>
        <weld body1="fixed_end1" anchor="-.48 0 0" />
    </equality>

    <actuator>
        <motor gear="10" joint="gear_joint" name="motor"/>
    </actuator>

    <sensor>
        <jointpos name="theta" joint="gear_joint"/>
        <jointvel name="theta_dot" joint="gear_joint"/>
    </sensor>
</mujoco>