<mujoco model="mesh_wheel">
    <asset>
        <!-- Load custom wheel mesh -->
        <mesh file="../../simulations/meshes/reaction_wheel.STL" scale="0.01 0.01 0.01"/>
        <texture name="grid" type="2d" builtin="checker" width="512" height="512" rgb1=".1 .2 .3" rgb2=".2 .3 .4"/>
        <material name="grid" texture="grid" texrepeat="1 1" texuniform="true" reflectance=".2"/>
    </asset>

    <worldbody>
        <light diffuse=".5 .5 .5" pos="0 0 3" dir="0 0 -1" />
        <geom type="plane" size="2 2 .1" material="grid" />


            <!-- Wheel with custom mesh -->
            <body name="wheel" pos="0 0 0">
                <geom type="mesh" mesh="reaction_wheel" mass=".1" pos="-.8 0 0"/>
                
                <!-- Joint for wheel rotation -->
                <joint name="hinge" type="hinge" pos="0 0 .82" axis="0 1 0" />
            </body>
    </worldbody>
    <actuator>
        <motor gear="1" joint="hinge" name="motor"/>
    </actuator>
</mujoco>