<mujoco>
  <option timestep="0.01" integrator="RK4" gravity="0 0 -9.81">
    <flag energy="enable" contact="enable" />
  </option>
  <asset>
    <texture name="grid" type="2d" builtin="checker" width="512" height="512" rgb1=".9 .9 .9" rgb2=".1 .1 .1" />
    <material name="grid" texture="grid" texrepeat="10 10" texuniform="true" reflectance=".2" />
  </asset>
  
  <worldbody>
    <light diffuse=".5 .5 .5" pos="0 0 3" dir="0 0 -1" />
    <geom type="plane" size="1 1 .1" material="grid"/>
    
    <body name="car" pos=" 0 0 .5">
      <joint type="free"/>
      <geom type="box" size=".25 .2 .05" rgba="0 .9 0 1" mass="30"/>
      <body name="front" pos="-.25 0 0">
        <geom type="box" size=".025 .025 .02" rgba=".5 .9 0 1" mass=".01"/>
      </body>
      <site name="chassis_frame" pos="0 0 0" size=".01" />
      <site name="rangefinder_frame" pos=".3 0 0" euler="0 90 0" size=".01" />
      <body name="wheel_r" pos="0 -.26 0" euler="90 0 0">
        <joint name="wheel_r_axis" type="hinge" axis="0 0 1" damping=".03" />
        <geom type="cylinder" size=".1 .05" rgba="1 0 0 1" mass="10" />
      </body>
      
      <body name="wheel_l" pos="0 .26 0" euler="90 0 0">
        <joint name="wheel_l_axis" type="hinge" axis="0 0 1" damping=".03" />
        <geom type="cylinder" size=".1 .05" rgba="1 1 0 1" mass="10" />
      </body>
    </body>
  </worldbody>
  
  <actuator>
    <motor name="torque_wheel_r" joint="wheel_r_axis" gear="1" ctrllimited="true" ctrlrange="-10 10" />
    <motor name="torque_wheel_l" joint="wheel_l_axis" gear="1" ctrllimited="true" ctrlrange="-10 10"/>
  </actuator>
  
  <sensor>
    <velocimeter name="car_vel" site="chassis_frame" />
    <gyro name="car_gyro" site="chassis_frame" />
    <magnetometer name="compass" site="chassis_frame" />
  </sensor>
</mujoco>